---
title: "JS 예외 처리"
execrpt: "js 예외 처리 방식"
toc: true
toc_sticky: true
categories:
  - JS
tags:
  - JS
last_modified_at: 2022-09-17
---
# 에러의 종류
- syntax Error : 문법에러. 코딩상의 실수이므로 수정하지 않으면 프로그램이 동작하지 않음.
- Runtime Error : 프로그램 작성 과정에서 논리상의 오류로 미처 대응하지 못한 상황이 발생하는 경우. -> 처리하지 않을 경우 프로그램이 중단된다.
  
`try catch`
```js
const data = [1,2,3];
/**
 * 먼저 try{...}안의 코드가 실행된다.
 * 에러가 없다면, try 안의 마지막 줄까지 실행되고, catch 블록은 건너뛴다.
 * 에러가 있다면, try 안 코드의 실행이 중단되고, catch(err) 블록으로 제어 흐름이 넘어간다.
 * 변수 err(아무 이름이나 상관 없음)는 무슨 일이 일어났는지에 대한 설명이 담긴 에러 객체를 포함한다.
 * try-catch로 발생할 에러에 대비하면 에러가 발생하더라도 프로그램이 중단되지 않는다.
 */
try{
    for(let i =0; i< 10; i++){
        console.log(data[i].toFixed(2));
    }
}catch(err){
    console.log(`${err.name} 에러 발생`);
    console.error(err.message);
    // 에러정보 전체
    // console.error(err);
}finally{
    // 에러 발생 여부에 상관없이 무조건 맨 마지막에 실행되는 블록.(생략가능)
    console.log(`배열 탐색 종료.`);
}
```

`에러 객체`
```js
// 에러 객체 생성, 생성자 파라미터로 에러의 내용 전달.
let err = new Error(`프로그램 에러!`);
console.log(`에러이름 : ${err.name}`); // Error
console.log(`에러내용 : ${err.message}`); // 프로그램 에러!
// 개발자가 직접 에러를 발생시킬 수 있다.
// 이 구문을 실제 에러로 인식하기 때문에 프로그램이 이 위치에서 중단된다.
throw err;
console.log(`콘솔에 나타나지 않음 ㅠ`); // 콘솔로그는 실행되지 않는다.
```
  
`에러에 대한 예외처리`
```js
let err = new Error(`프로그램 에러!`);
try{
    // throw 구문은 그 자체를 에러로 인식하기 때문에 try-catch 처리가 가능하다.
    throw err;
}catch(err){
    console.log(`에러이름 : ${err.name}`);
    console.log(`에러내용 : ${err.message}`);
}
// 에러 상황을 try-catch로 처리했으므로 프로그램이 중단되지 않고 무사히 종료할 수 있다.
console.log(`에러가 발생해도 나타남!`);
```

`에러 객체를 활용한 예외처리`  
[Scope](https://poiemaweb.com/js-scope)
```js
foo = (x,y) =>{
    if(x<0){
        // 함수 안에서 에러를 강제로 발생시키면 이 함수를 호출하는 위치를 에러로 인식.
        throw new Error(`x가 0보다 작습니다.`);
    }
    if(y<0){
        throw new Error(`y가 0보다 작습니다.`);
    }
    return x + y;
}
/**
 * try블록 안의 코드는 최소화 하는 것이 프로그램 효율에 좋다.
 * 그래서 k값을 정상적으로 리턴 받았다면 그 결과값을 활용하는 처리는 try블록 밖에서 하는것이 좋다.
 * 에러 점검이 끝난 후 try-catch 블록 밖에서 k값을 활용하려면
 * 변수의 선언 위치가 try블록보다 상위에 위치해야 한다. : 변수의 스코프 규칙.
 */
const a = null;
const b = null;
try{
    a=foo(-1,10);
}catch(err){
    // 이 블록으로 전달되는 err객체는 위의 Error 클래스의 객체이다.
    console.log(`에러이름 : ${err.name}`); // Error
    console.log(`에러내용 : ${err.message}`); // x가 0보다 작습니다.
}
console.log(a); // null
console.log(b); // null
```

`사용자 정의 에러`  
에러의 종류를 세분화 하기 위해 기본 Error클래스의 기능을 확장하여 개발자가 직접 에러에 대한 경우의 수를 정의할 수 있다.  
```js
class XlessError extends Error{
    // 자식 클래스가 생성자를 갖을 경우 부모의 생성자를 반드시 강제호출해야 한다. : super(...)
    constructor(msg){
        super(msg);
        super.name = `XlessError`;
    }
}
class YlessError extends Error{
    constructor(msg){
        super(msg);
        super.name = `YlessError`;
    }
}
foo = (x,y) =>{
    if(x<0){
        throw new XlessError(`x가 0보다 작습니다.`);
    }
    if(y<0){
        throw new YlessError(`y가 0보다 작습니다.`);
    }
    return x + y;
}
const a = null;
const b = null;
try{
    a=foo(-1,10);
}catch(err){
    console.log(`에러이름 : ${err.name}`); // XlessError
    console.log(`에러내용 : ${err.message}`); // x가 0보다 작습니다.
}
console.log(a); //null
console.log(b); //null
```